# 例外処理

最初の num を 10倍する処理

```python
num    = 2
result = float(num) * 10
print(f'{num}の10倍 >>>>', result)
```

```python
2の10倍 >>>> 20.0
```

num を数値以外にするとエラーになる

```python
num    = 'ほげ'
result = float(num) * 10
print(f'{num}の10倍 >>>>', result)
```

```python
Traceback (most recent call last):
  File "hoge.py", line 3, in <module>
    result = float(num) * 10
ValueError: could not convert string to float: 'ほげ'
```

`try` 〜 `except` で例外処理を追加

```python
try:
    num    = 'ほげ'
    result = float(num) * 10
    print(f'{num}の10倍 >>>>', result)
except ValueError as ex:
    print('エラーだよ', ex)
```

```python
エラーだよ could not convert string to float: 'ほげ'
```

- エラーの種類 ： 他には **TypeError** **NameError** など

- 例外変数を使わない場合は、 `ex` 省略してOK

```python
except ValueError:
    print('エラーだよ')
```

## 例外が発生した場合、しなかった場合の処理

- `except` ： 例外が発生した場合

- `else` ： 例外が発生しなかった場合

- `finally` ： 例外が発生してもしなくても実行される

```python
try:
    num    = 2
    result = float(num) * 10
    print(f'{num}の10倍 >>>>', result)
except ValueError:
    print('エラーだよ')
else:
    print('エラーが発生しなかったよ')
finally:
    print('エラーがあってもなくても実行される処理')
```

```python
2の10倍 >>>> 20.0
エラーが発生しなかったよ
エラーがあってもなくても実行される処理
```

↑ 同じ処理 例外発生させた版

```python
try:
    num    = 'ほげ'
    result = float(num) * 10
    print(f'{num}の10倍 >>>>', result)
except ValueError:
    print('エラーだよ')
else:
    print('エラーが発生しなかったよ')
finally:
    print('エラーがあってもなくても実行される処理')
```

```python
エラーだよ
エラーがあってもなくても実行される処理
```
